# 古代神殿の宝物回廊トラップ — チャットコマンド版（1行ずつチャットに貼り付け）
# 建てたい場所に立って、動かずに順番に実行する（~はプレイヤー相対座標）

/fill ~2 ~0 ~3 ~5 ~0 ~3 stone
/setblock ~2 ~0 ~4 stone
/fill ~3 ~0 ~4 ~4 ~0 ~4 lava
/setblock ~5 ~0 ~4 stone
/setblock ~2 ~0 ~5 stone
/fill ~3 ~0 ~5 ~4 ~0 ~5 lava
/setblock ~5 ~0 ~5 stone
/setblock ~2 ~0 ~6 stone
/fill ~3 ~0 ~6 ~4 ~0 ~6 lava
/setblock ~5 ~0 ~6 stone
/fill ~2 ~0 ~7 ~5 ~0 ~7 stone
/fill ~2 ~1 ~3 ~5 ~1 ~3 stone
/setblock ~2 ~1 ~4 stone
/fill ~3 ~1 ~4 ~4 ~1 ~4 glass
/setblock ~5 ~1 ~4 stone
/setblock ~2 ~1 ~5 stone
/fill ~3 ~1 ~5 ~4 ~1 ~5 glass
/setblock ~5 ~1 ~5 stone
/setblock ~2 ~1 ~6 stone
/fill ~3 ~1 ~6 ~4 ~1 ~6 glass
/setblock ~5 ~1 ~6 stone
/fill ~2 ~1 ~7 ~5 ~1 ~7 stone
/setblock ~2 ~2 ~3 stone_bricks
/setblock ~3 ~2 ~3 glowstone
/fill ~4 ~2 ~3 ~5 ~2 ~3 stone_bricks
/setblock ~2 ~2 ~4 glowstone
/setblock ~5 ~2 ~4 stone_bricks
/setblock ~2 ~2 ~5 stone_bricks
/setblock ~5 ~2 ~5 stone_bricks
/setblock ~2 ~2 ~6 stone_bricks
/setblock ~5 ~2 ~6 glowstone
/fill ~2 ~2 ~7 ~3 ~2 ~7 stone_bricks
/setblock ~4 ~2 ~7 glowstone
/setblock ~5 ~2 ~7 stone_bricks
/fill ~2 ~3 ~3 ~5 ~3 ~3 stone_bricks
/setblock ~2 ~3 ~4 stone_bricks
/setblock ~5 ~3 ~4 mossy_stone_bricks
/setblock ~2 ~3 ~5 stone_bricks
/setblock ~5 ~3 ~5 stone_bricks
/setblock ~2 ~3 ~6 stone_bricks
/setblock ~5 ~3 ~6 stone_bricks
/fill ~2 ~3 ~7 ~5 ~3 ~7 stone_bricks
/fill ~2 ~4 ~3 ~5 ~4 ~3 stone_bricks
/setblock ~2 ~4 ~4 stone_bricks
/setblock ~5 ~4 ~4 stone_bricks
/setblock ~2 ~4 ~5 mossy_stone_bricks
/setblock ~5 ~4 ~5 stone_bricks
/setblock ~2 ~4 ~6 stone_bricks
/setblock ~5 ~4 ~6 stone_bricks
/fill ~2 ~4 ~7 ~5 ~4 ~7 stone_bricks
/fill ~2 ~5 ~3 ~5 ~5 ~3 stone_bricks
/setblock ~2 ~5 ~4 stone_bricks
/setblock ~5 ~5 ~4 stone_bricks
/setblock ~2 ~5 ~5 stone_bricks
/setblock ~5 ~5 ~5 stone_bricks
/setblock ~2 ~5 ~6 stone_bricks
/setblock ~5 ~5 ~6 stone_bricks
/fill ~2 ~5 ~7 ~5 ~5 ~7 stone_bricks
/fill ~2 ~6 ~3 ~5 ~6 ~3 stone_bricks
/setblock ~2 ~6 ~4 stone_bricks
/setblock ~5 ~6 ~4 stone_bricks
/setblock ~2 ~6 ~5 stone_bricks
/fill ~3 ~6 ~5 ~4 ~6 ~5 stone
/setblock ~5 ~6 ~5 stone_bricks
/setblock ~2 ~6 ~6 stone_bricks
/setblock ~5 ~6 ~6 stone_bricks
/fill ~2 ~6 ~7 ~5 ~6 ~7 stone_bricks
/fill ~0 ~7 ~3 ~7 ~7 ~3 stone
/setblock ~0 ~7 ~4 stone
/setblock ~2 ~7 ~4 stone
/setblock ~5 ~7 ~4 stone
/setblock ~7 ~7 ~4 stone
/fill ~0 ~7 ~5 ~1 ~7 ~5 stone
/fill ~6 ~7 ~5 ~7 ~7 ~5 stone
/setblock ~0 ~7 ~6 stone
/setblock ~2 ~7 ~6 stone
/setblock ~5 ~7 ~6 stone
/setblock ~7 ~7 ~6 stone
/fill ~0 ~7 ~7 ~7 ~7 ~7 stone
/fill ~1 ~8 ~0 ~6 ~8 ~0 stone_bricks
/fill ~1 ~8 ~1 ~6 ~8 ~1 stone_bricks
/fill ~1 ~8 ~2 ~6 ~8 ~2 stone_bricks
/fill ~1 ~8 ~3 ~6 ~8 ~3 stone_bricks
/fill ~3 ~8 ~4 ~4 ~8 ~4 stone_bricks
/setblock ~1 ~8 ~5 stone
/fill ~2 ~8 ~5 ~5 ~8 ~5 stone_bricks
/setblock ~6 ~8 ~5 stone
/fill ~3 ~8 ~6 ~4 ~8 ~6 stone_bricks
/fill ~1 ~8 ~7 ~4 ~8 ~7 stone_bricks
/setblock ~5 ~8 ~7 mossy_stone_bricks
/setblock ~6 ~8 ~7 stone_bricks
/setblock ~1 ~8 ~8 stone_bricks
/setblock ~2 ~8 ~8 mossy_stone_bricks
/fill ~3 ~8 ~8 ~6 ~8 ~8 stone_bricks
/fill ~1 ~8 ~9 ~3 ~8 ~9 stone_bricks
/setblock ~4 ~8 ~9 mossy_stone_bricks
/fill ~5 ~8 ~9 ~6 ~8 ~9 stone_bricks
/fill ~1 ~8 ~10 ~2 ~8 ~10 stone_bricks
/setblock ~3 ~8 ~10 mossy_stone_bricks
/fill ~4 ~8 ~10 ~6 ~8 ~10 stone_bricks
/fill ~1 ~9 ~0 ~6 ~9 ~0 stone_bricks
/fill ~1 ~9 ~1 ~6 ~9 ~1 stone_bricks
/setblock ~1 ~9 ~2 mossy_stone_bricks
/setblock ~2 ~9 ~2 chiseled_stone_bricks
/fill ~3 ~9 ~2 ~4 ~9 ~2 stone_bricks
/setblock ~5 ~9 ~2 chiseled_stone_bricks
/setblock ~6 ~9 ~2 stone_bricks
/setblock ~1 ~9 ~3 stone_bricks
/setblock ~6 ~9 ~3 stone_bricks
/setblock ~1 ~9 ~4 stone_bricks
/setblock ~6 ~9 ~4 mossy_stone_bricks
/setblock ~1 ~9 ~5 stone_bricks
/setblock ~6 ~9 ~5 stone_bricks
/setblock ~1 ~9 ~6 mossy_stone_bricks
/setblock ~6 ~9 ~6 stone_bricks
/setblock ~1 ~9 ~7 stone_bricks
/setblock ~2 ~9 ~7 chiseled_stone_bricks
/setblock ~5 ~9 ~7 chiseled_stone_bricks
/setblock ~6 ~9 ~7 stone_bricks
/setblock ~1 ~9 ~8 stone_bricks
/setblock ~6 ~9 ~8 stone_bricks
/setblock ~1 ~9 ~9 stone_bricks
/setblock ~6 ~9 ~9 mossy_stone_bricks
/setblock ~1 ~9 ~10 stone_bricks
/setblock ~6 ~9 ~10 stone_bricks
/setblock ~1 ~10 ~0 stone_bricks
/setblock ~2 ~10 ~0 glowstone
/fill ~3 ~10 ~0 ~4 ~10 ~0 chiseled_stone_bricks
/setblock ~5 ~10 ~0 glowstone
/setblock ~6 ~10 ~0 stone_bricks
/fill ~3 ~10 ~1 ~4 ~10 ~1 chiseled_stone_bricks
/setblock ~2 ~10 ~7 chiseled_stone_bricks
/setblock ~5 ~10 ~7 chiseled_stone_bricks
/setblock ~1 ~10 ~10 stone_bricks
/setblock ~6 ~10 ~10 stone_bricks
/fill ~1 ~11 ~0 ~6 ~11 ~0 stone_bricks
/fill ~3 ~11 ~1 ~4 ~11 ~1 glowstone
/setblock ~1 ~11 ~10 chiseled_stone_bricks
/fill ~2 ~11 ~10 ~5 ~11 ~10 stone_bricks
/setblock ~6 ~11 ~10 chiseled_stone_bricks

# ▼ 置き物は最後に（向きの調整は手動が確実）
/setblock ~1 ~7 ~4 redstone_torch
/setblock ~1 ~7 ~6 redstone_torch
/setblock ~6 ~7 ~4 redstone_torch
/setblock ~6 ~7 ~6 redstone_torch
/setblock ~2 ~7 ~5 redstone_wire
/setblock ~3 ~7 ~5 redstone_wire
/setblock ~4 ~7 ~5 redstone_wire
/setblock ~5 ~7 ~5 redstone_wire
/setblock ~1 ~8 ~4 sticky_piston
/setblock ~1 ~8 ~6 sticky_piston
/setblock ~6 ~8 ~4 sticky_piston
/setblock ~6 ~8 ~6 sticky_piston
/setblock ~2 ~9 ~5 stone_pressure_plate
/setblock ~3 ~9 ~5 stone_pressure_plate
/setblock ~4 ~9 ~5 stone_pressure_plate
/setblock ~5 ~9 ~5 stone_pressure_plate
/setblock ~1 ~10 ~7 torch
/setblock ~6 ~10 ~7 torch
