# 古代神殿の宝物回廊トラップ — 自動建築コード (MakeCode Python)
# 使い方:
#  1. Minecraft Education で C キー → Code Builder → MakeCode (Python)
#  2. このコードを貼り付けて実行ボタンを押す
#  3. 建てたい場所に立って、チャットで build と入力（建築中は動かない！）
# 建物はプレイヤーの足元を基準に、東(x+)・南(z+)方向に建ちます。

def build():
    blocks.fill(STONE, pos(2, 0, 3), pos(5, 0, 3))
    blocks.place(STONE, pos(2, 0, 4))
    blocks.fill(LAVA, pos(3, 0, 4), pos(4, 0, 4))
    blocks.place(STONE, pos(5, 0, 4))
    blocks.place(STONE, pos(2, 0, 5))
    blocks.fill(LAVA, pos(3, 0, 5), pos(4, 0, 5))
    blocks.place(STONE, pos(5, 0, 5))
    blocks.place(STONE, pos(2, 0, 6))
    blocks.fill(LAVA, pos(3, 0, 6), pos(4, 0, 6))
    blocks.place(STONE, pos(5, 0, 6))
    blocks.fill(STONE, pos(2, 0, 7), pos(5, 0, 7))
    blocks.fill(STONE, pos(2, 1, 3), pos(5, 1, 3))
    blocks.place(STONE, pos(2, 1, 4))
    blocks.fill(GLASS, pos(3, 1, 4), pos(4, 1, 4))
    blocks.place(STONE, pos(5, 1, 4))
    blocks.place(STONE, pos(2, 1, 5))
    blocks.fill(GLASS, pos(3, 1, 5), pos(4, 1, 5))
    blocks.place(STONE, pos(5, 1, 5))
    blocks.place(STONE, pos(2, 1, 6))
    blocks.fill(GLASS, pos(3, 1, 6), pos(4, 1, 6))
    blocks.place(STONE, pos(5, 1, 6))
    blocks.fill(STONE, pos(2, 1, 7), pos(5, 1, 7))
    blocks.place(STONE_BRICKS, pos(2, 2, 3))
    blocks.place(GLOWSTONE, pos(3, 2, 3))
    blocks.fill(STONE_BRICKS, pos(4, 2, 3), pos(5, 2, 3))
    blocks.place(GLOWSTONE, pos(2, 2, 4))
    blocks.place(STONE_BRICKS, pos(5, 2, 4))
    blocks.place(STONE_BRICKS, pos(2, 2, 5))
    blocks.place(STONE_BRICKS, pos(5, 2, 5))
    blocks.place(STONE_BRICKS, pos(2, 2, 6))
    blocks.place(GLOWSTONE, pos(5, 2, 6))
    blocks.fill(STONE_BRICKS, pos(2, 2, 7), pos(3, 2, 7))
    blocks.place(GLOWSTONE, pos(4, 2, 7))
    blocks.place(STONE_BRICKS, pos(5, 2, 7))
    blocks.fill(STONE_BRICKS, pos(2, 3, 3), pos(5, 3, 3))
    blocks.place(STONE_BRICKS, pos(2, 3, 4))
    blocks.place(MOSSY_STONE_BRICKS, pos(5, 3, 4))
    blocks.place(STONE_BRICKS, pos(2, 3, 5))
    blocks.place(STONE_BRICKS, pos(5, 3, 5))
    blocks.place(STONE_BRICKS, pos(2, 3, 6))
    blocks.place(STONE_BRICKS, pos(5, 3, 6))
    blocks.fill(STONE_BRICKS, pos(2, 3, 7), pos(5, 3, 7))
    blocks.fill(STONE_BRICKS, pos(2, 4, 3), pos(5, 4, 3))
    blocks.place(STONE_BRICKS, pos(2, 4, 4))
    blocks.place(STONE_BRICKS, pos(5, 4, 4))
    blocks.place(MOSSY_STONE_BRICKS, pos(2, 4, 5))
    blocks.place(STONE_BRICKS, pos(5, 4, 5))
    blocks.place(STONE_BRICKS, pos(2, 4, 6))
    blocks.place(STONE_BRICKS, pos(5, 4, 6))
    blocks.fill(STONE_BRICKS, pos(2, 4, 7), pos(5, 4, 7))
    blocks.fill(STONE_BRICKS, pos(2, 5, 3), pos(5, 5, 3))
    blocks.place(STONE_BRICKS, pos(2, 5, 4))
    blocks.place(STONE_BRICKS, pos(5, 5, 4))
    blocks.place(STONE_BRICKS, pos(2, 5, 5))
    blocks.place(STONE_BRICKS, pos(5, 5, 5))
    blocks.place(STONE_BRICKS, pos(2, 5, 6))
    blocks.place(STONE_BRICKS, pos(5, 5, 6))
    blocks.fill(STONE_BRICKS, pos(2, 5, 7), pos(5, 5, 7))
    blocks.fill(STONE_BRICKS, pos(2, 6, 3), pos(5, 6, 3))
    blocks.place(STONE_BRICKS, pos(2, 6, 4))
    blocks.place(STONE_BRICKS, pos(5, 6, 4))
    blocks.place(STONE_BRICKS, pos(2, 6, 5))
    blocks.fill(STONE, pos(3, 6, 5), pos(4, 6, 5))
    blocks.place(STONE_BRICKS, pos(5, 6, 5))
    blocks.place(STONE_BRICKS, pos(2, 6, 6))
    blocks.place(STONE_BRICKS, pos(5, 6, 6))
    blocks.fill(STONE_BRICKS, pos(2, 6, 7), pos(5, 6, 7))
    blocks.fill(STONE, pos(0, 7, 3), pos(7, 7, 3))
    blocks.place(STONE, pos(0, 7, 4))
    blocks.place(STONE, pos(2, 7, 4))
    blocks.place(STONE, pos(5, 7, 4))
    blocks.place(STONE, pos(7, 7, 4))
    blocks.fill(STONE, pos(0, 7, 5), pos(1, 7, 5))
    blocks.fill(STONE, pos(6, 7, 5), pos(7, 7, 5))
    blocks.place(STONE, pos(0, 7, 6))
    blocks.place(STONE, pos(2, 7, 6))
    blocks.place(STONE, pos(5, 7, 6))
    blocks.place(STONE, pos(7, 7, 6))
    blocks.fill(STONE, pos(0, 7, 7), pos(7, 7, 7))
    blocks.fill(STONE_BRICKS, pos(1, 8, 0), pos(6, 8, 0))
    blocks.fill(STONE_BRICKS, pos(1, 8, 1), pos(6, 8, 1))
    blocks.fill(STONE_BRICKS, pos(1, 8, 2), pos(6, 8, 2))
    blocks.fill(STONE_BRICKS, pos(1, 8, 3), pos(6, 8, 3))
    blocks.fill(STONE_BRICKS, pos(3, 8, 4), pos(4, 8, 4))
    blocks.place(STONE, pos(1, 8, 5))
    blocks.fill(STONE_BRICKS, pos(2, 8, 5), pos(5, 8, 5))
    blocks.place(STONE, pos(6, 8, 5))
    blocks.fill(STONE_BRICKS, pos(3, 8, 6), pos(4, 8, 6))
    blocks.fill(STONE_BRICKS, pos(1, 8, 7), pos(4, 8, 7))
    blocks.place(MOSSY_STONE_BRICKS, pos(5, 8, 7))
    blocks.place(STONE_BRICKS, pos(6, 8, 7))
    blocks.place(STONE_BRICKS, pos(1, 8, 8))
    blocks.place(MOSSY_STONE_BRICKS, pos(2, 8, 8))
    blocks.fill(STONE_BRICKS, pos(3, 8, 8), pos(6, 8, 8))
    blocks.fill(STONE_BRICKS, pos(1, 8, 9), pos(3, 8, 9))
    blocks.place(MOSSY_STONE_BRICKS, pos(4, 8, 9))
    blocks.fill(STONE_BRICKS, pos(5, 8, 9), pos(6, 8, 9))
    blocks.fill(STONE_BRICKS, pos(1, 8, 10), pos(2, 8, 10))
    blocks.place(MOSSY_STONE_BRICKS, pos(3, 8, 10))
    blocks.fill(STONE_BRICKS, pos(4, 8, 10), pos(6, 8, 10))
    blocks.fill(STONE_BRICKS, pos(1, 9, 0), pos(6, 9, 0))
    blocks.fill(STONE_BRICKS, pos(1, 9, 1), pos(6, 9, 1))
    blocks.place(MOSSY_STONE_BRICKS, pos(1, 9, 2))
    blocks.place(CHISELED_STONE_BRICKS, pos(2, 9, 2))
    blocks.fill(STONE_BRICKS, pos(3, 9, 2), pos(4, 9, 2))
    blocks.place(CHISELED_STONE_BRICKS, pos(5, 9, 2))
    blocks.place(STONE_BRICKS, pos(6, 9, 2))
    blocks.place(STONE_BRICKS, pos(1, 9, 3))
    blocks.place(STONE_BRICKS, pos(6, 9, 3))
    blocks.place(STONE_BRICKS, pos(1, 9, 4))
    blocks.place(MOSSY_STONE_BRICKS, pos(6, 9, 4))
    blocks.place(STONE_BRICKS, pos(1, 9, 5))
    blocks.place(STONE_BRICKS, pos(6, 9, 5))
    blocks.place(MOSSY_STONE_BRICKS, pos(1, 9, 6))
    blocks.place(STONE_BRICKS, pos(6, 9, 6))
    blocks.place(STONE_BRICKS, pos(1, 9, 7))
    blocks.place(CHISELED_STONE_BRICKS, pos(2, 9, 7))
    blocks.place(CHISELED_STONE_BRICKS, pos(5, 9, 7))
    blocks.place(STONE_BRICKS, pos(6, 9, 7))
    blocks.place(STONE_BRICKS, pos(1, 9, 8))
    blocks.place(STONE_BRICKS, pos(6, 9, 8))
    blocks.place(STONE_BRICKS, pos(1, 9, 9))
    blocks.place(MOSSY_STONE_BRICKS, pos(6, 9, 9))
    blocks.place(STONE_BRICKS, pos(1, 9, 10))
    blocks.place(STONE_BRICKS, pos(6, 9, 10))
    blocks.place(STONE_BRICKS, pos(1, 10, 0))
    blocks.place(GLOWSTONE, pos(2, 10, 0))
    blocks.fill(CHISELED_STONE_BRICKS, pos(3, 10, 0), pos(4, 10, 0))
    blocks.place(GLOWSTONE, pos(5, 10, 0))
    blocks.place(STONE_BRICKS, pos(6, 10, 0))
    blocks.fill(CHISELED_STONE_BRICKS, pos(3, 10, 1), pos(4, 10, 1))
    blocks.place(CHISELED_STONE_BRICKS, pos(2, 10, 7))
    blocks.place(CHISELED_STONE_BRICKS, pos(5, 10, 7))
    blocks.place(STONE_BRICKS, pos(1, 10, 10))
    blocks.place(STONE_BRICKS, pos(6, 10, 10))
    blocks.fill(STONE_BRICKS, pos(1, 11, 0), pos(6, 11, 0))
    blocks.fill(GLOWSTONE, pos(3, 11, 1), pos(4, 11, 1))
    blocks.place(CHISELED_STONE_BRICKS, pos(1, 11, 10))
    blocks.fill(STONE_BRICKS, pos(2, 11, 10), pos(5, 11, 10))
    blocks.place(CHISELED_STONE_BRICKS, pos(6, 11, 10))
    # ▼ 置き物（たいまつ・ドア等）は自動設置が不安定なので手で置くのがおすすめ
    #   レッドストーントーチ → 図の位置 x=1, 8段目, z=4
    #   レッドストーントーチ → 図の位置 x=1, 8段目, z=6
    #   レッドストーントーチ → 図の位置 x=6, 8段目, z=4
    #   レッドストーントーチ → 図の位置 x=6, 8段目, z=6
    #   レッドストーンダスト → 図の位置 x=2, 8段目, z=5
    #   レッドストーンダスト → 図の位置 x=3, 8段目, z=5
    #   レッドストーンダスト → 図の位置 x=4, 8段目, z=5
    #   レッドストーンダスト → 図の位置 x=5, 8段目, z=5
    #   粘着ピストン → 図の位置 x=1, 9段目, z=4
    #   粘着ピストン → 図の位置 x=1, 9段目, z=6
    #   粘着ピストン → 図の位置 x=6, 9段目, z=4
    #   粘着ピストン → 図の位置 x=6, 9段目, z=6
    #   石の感圧板 → 図の位置 x=2, 10段目, z=5
    #   石の感圧板 → 図の位置 x=3, 10段目, z=5
    #   石の感圧板 → 図の位置 x=4, 10段目, z=5
    #   石の感圧板 → 図の位置 x=5, 10段目, z=5
    #   たいまつ → 図の位置 x=1, 11段目, z=7
    #   たいまつ → 図の位置 x=6, 11段目, z=7

player.on_chat("build", build)
