# ちいさな木の家 — チャットコマンド版（1行ずつチャットに貼り付け）
# 建てたい場所に立って、動かずに順番に実行する（~はプレイヤー相対座標）

/fill ~0 ~0 ~0 ~8 ~0 ~0 cobblestone
/fill ~0 ~0 ~1 ~8 ~0 ~1 cobblestone
/fill ~0 ~0 ~2 ~8 ~0 ~2 cobblestone
/fill ~0 ~0 ~3 ~8 ~0 ~3 cobblestone
/fill ~0 ~0 ~4 ~8 ~0 ~4 cobblestone
/fill ~0 ~0 ~5 ~8 ~0 ~5 cobblestone
/fill ~0 ~0 ~6 ~8 ~0 ~6 cobblestone
/setblock ~0 ~1 ~0 oak_log
/fill ~1 ~1 ~0 ~7 ~1 ~0 oak_planks
/setblock ~8 ~1 ~0 oak_log
/setblock ~0 ~1 ~1 oak_planks
/setblock ~8 ~1 ~1 oak_planks
/setblock ~0 ~1 ~2 oak_planks
/setblock ~8 ~1 ~2 oak_planks
/setblock ~0 ~1 ~3 oak_planks
/setblock ~8 ~1 ~3 oak_planks
/setblock ~0 ~1 ~4 oak_planks
/setblock ~8 ~1 ~4 oak_planks
/setblock ~0 ~1 ~5 oak_planks
/setblock ~8 ~1 ~5 oak_planks
/setblock ~0 ~1 ~6 oak_log
/fill ~1 ~1 ~6 ~3 ~1 ~6 oak_planks
/fill ~5 ~1 ~6 ~7 ~1 ~6 oak_planks
/setblock ~8 ~1 ~6 oak_log
/setblock ~0 ~2 ~0 oak_log
/setblock ~1 ~2 ~0 oak_planks
/setblock ~2 ~2 ~0 glass
/setblock ~3 ~2 ~0 oak_planks
/setblock ~4 ~2 ~0 glass
/setblock ~5 ~2 ~0 oak_planks
/setblock ~6 ~2 ~0 glass
/setblock ~7 ~2 ~0 oak_planks
/setblock ~8 ~2 ~0 oak_log
/setblock ~0 ~2 ~1 oak_planks
/setblock ~8 ~2 ~1 oak_planks
/setblock ~0 ~2 ~2 oak_planks
/setblock ~8 ~2 ~2 oak_planks
/setblock ~0 ~2 ~3 glass
/setblock ~8 ~2 ~3 glass
/setblock ~0 ~2 ~4 oak_planks
/setblock ~8 ~2 ~4 oak_planks
/setblock ~0 ~2 ~5 oak_planks
/setblock ~8 ~2 ~5 oak_planks
/setblock ~0 ~2 ~6 oak_log
/setblock ~1 ~2 ~6 oak_planks
/setblock ~2 ~2 ~6 glass
/setblock ~3 ~2 ~6 oak_planks
/setblock ~5 ~2 ~6 oak_planks
/setblock ~6 ~2 ~6 glass
/setblock ~7 ~2 ~6 oak_planks
/setblock ~8 ~2 ~6 oak_log
/setblock ~0 ~3 ~0 oak_log
/fill ~1 ~3 ~0 ~7 ~3 ~0 oak_planks
/setblock ~8 ~3 ~0 oak_log
/setblock ~0 ~3 ~1 oak_planks
/setblock ~8 ~3 ~1 oak_planks
/setblock ~0 ~3 ~2 oak_planks
/setblock ~8 ~3 ~2 oak_planks
/setblock ~0 ~3 ~3 oak_planks
/setblock ~8 ~3 ~3 oak_planks
/setblock ~0 ~3 ~4 oak_planks
/setblock ~8 ~3 ~4 oak_planks
/setblock ~0 ~3 ~5 oak_planks
/setblock ~8 ~3 ~5 oak_planks
/setblock ~0 ~3 ~6 oak_log
/fill ~1 ~3 ~6 ~7 ~3 ~6 oak_planks
/setblock ~8 ~3 ~6 oak_log
/fill ~0 ~4 ~0 ~8 ~4 ~0 spruce_planks
/fill ~0 ~4 ~1 ~8 ~4 ~1 spruce_planks
/setblock ~0 ~4 ~2 oak_planks
/setblock ~8 ~4 ~2 oak_planks
/setblock ~0 ~4 ~3 oak_planks
/setblock ~8 ~4 ~3 oak_planks
/setblock ~0 ~4 ~4 oak_planks
/setblock ~8 ~4 ~4 oak_planks
/fill ~0 ~4 ~5 ~8 ~4 ~5 spruce_planks
/fill ~0 ~4 ~6 ~8 ~4 ~6 spruce_planks
/fill ~0 ~5 ~2 ~8 ~5 ~2 spruce_planks
/setblock ~0 ~5 ~3 oak_planks
/setblock ~8 ~5 ~3 oak_planks
/fill ~0 ~5 ~4 ~8 ~5 ~4 spruce_planks
/fill ~0 ~6 ~3 ~8 ~6 ~3 spruce_planks

# ▼ 置き物は最後に（向きの調整は手動が確実）
/setblock ~4 ~1 ~6 wooden_door
/setblock ~1 ~1 ~1 torch
/setblock ~1 ~1 ~5 torch
/setblock ~7 ~1 ~1 torch
/setblock ~7 ~1 ~5 torch
