# ちいさな木の家 — 自動建築コード (MakeCode Python)
# 使い方:
#  1. Minecraft Education で C キー → Code Builder → MakeCode (Python)
#  2. このコードを貼り付けて実行ボタンを押す
#  3. 建てたい場所に立って、チャットで build と入力（建築中は動かない！）
# 建物はプレイヤーの足元を基準に、東(x+)・南(z+)方向に建ちます。
# ブロック定数は実機のCode Builder（Education 1.21.133）で検証済み。
# ランタンと石レンガのハーフはMakeCodeに無いため近い見た目で代用される。
#       正確に建てたい場合は commands.txt を使う（正しいIDで置かれる）。

def build():
    blocks.fill(COBBLESTONE, pos(0, 0, 0), pos(8, 0, 0))
    blocks.fill(COBBLESTONE, pos(0, 0, 1), pos(8, 0, 1))
    blocks.fill(COBBLESTONE, pos(0, 0, 2), pos(8, 0, 2))
    blocks.fill(COBBLESTONE, pos(0, 0, 3), pos(8, 0, 3))
    blocks.fill(COBBLESTONE, pos(0, 0, 4), pos(8, 0, 4))
    blocks.fill(COBBLESTONE, pos(0, 0, 5), pos(8, 0, 5))
    blocks.fill(COBBLESTONE, pos(0, 0, 6), pos(8, 0, 6))
    blocks.place(LOG_OAK, pos(0, 1, 0))
    blocks.fill(PLANKS_OAK, pos(1, 1, 0), pos(7, 1, 0))
    blocks.place(LOG_OAK, pos(8, 1, 0))
    blocks.place(PLANKS_OAK, pos(0, 1, 1))
    blocks.place(PLANKS_OAK, pos(8, 1, 1))
    blocks.place(PLANKS_OAK, pos(0, 1, 2))
    blocks.place(PLANKS_OAK, pos(8, 1, 2))
    blocks.place(PLANKS_OAK, pos(0, 1, 3))
    blocks.place(PLANKS_OAK, pos(8, 1, 3))
    blocks.place(PLANKS_OAK, pos(0, 1, 4))
    blocks.place(PLANKS_OAK, pos(8, 1, 4))
    blocks.place(PLANKS_OAK, pos(0, 1, 5))
    blocks.place(PLANKS_OAK, pos(8, 1, 5))
    blocks.place(LOG_OAK, pos(0, 1, 6))
    blocks.fill(PLANKS_OAK, pos(1, 1, 6), pos(3, 1, 6))
    blocks.fill(PLANKS_OAK, pos(5, 1, 6), pos(7, 1, 6))
    blocks.place(LOG_OAK, pos(8, 1, 6))
    blocks.place(LOG_OAK, pos(0, 2, 0))
    blocks.place(PLANKS_OAK, pos(1, 2, 0))
    blocks.place(GLASS, pos(2, 2, 0))
    blocks.place(PLANKS_OAK, pos(3, 2, 0))
    blocks.place(GLASS, pos(4, 2, 0))
    blocks.place(PLANKS_OAK, pos(5, 2, 0))
    blocks.place(GLASS, pos(6, 2, 0))
    blocks.place(PLANKS_OAK, pos(7, 2, 0))
    blocks.place(LOG_OAK, pos(8, 2, 0))
    blocks.place(PLANKS_OAK, pos(0, 2, 1))
    blocks.place(PLANKS_OAK, pos(8, 2, 1))
    blocks.place(PLANKS_OAK, pos(0, 2, 2))
    blocks.place(PLANKS_OAK, pos(8, 2, 2))
    blocks.place(GLASS, pos(0, 2, 3))
    blocks.place(GLASS, pos(8, 2, 3))
    blocks.place(PLANKS_OAK, pos(0, 2, 4))
    blocks.place(PLANKS_OAK, pos(8, 2, 4))
    blocks.place(PLANKS_OAK, pos(0, 2, 5))
    blocks.place(PLANKS_OAK, pos(8, 2, 5))
    blocks.place(LOG_OAK, pos(0, 2, 6))
    blocks.place(PLANKS_OAK, pos(1, 2, 6))
    blocks.place(GLASS, pos(2, 2, 6))
    blocks.place(PLANKS_OAK, pos(3, 2, 6))
    blocks.place(PLANKS_OAK, pos(5, 2, 6))
    blocks.place(GLASS, pos(6, 2, 6))
    blocks.place(PLANKS_OAK, pos(7, 2, 6))
    blocks.place(LOG_OAK, pos(8, 2, 6))
    blocks.place(LOG_OAK, pos(0, 3, 0))
    blocks.fill(PLANKS_OAK, pos(1, 3, 0), pos(7, 3, 0))
    blocks.place(LOG_OAK, pos(8, 3, 0))
    blocks.place(PLANKS_OAK, pos(0, 3, 1))
    blocks.place(PLANKS_OAK, pos(8, 3, 1))
    blocks.place(PLANKS_OAK, pos(0, 3, 2))
    blocks.place(PLANKS_OAK, pos(8, 3, 2))
    blocks.place(PLANKS_OAK, pos(0, 3, 3))
    blocks.place(PLANKS_OAK, pos(8, 3, 3))
    blocks.place(PLANKS_OAK, pos(0, 3, 4))
    blocks.place(PLANKS_OAK, pos(8, 3, 4))
    blocks.place(PLANKS_OAK, pos(0, 3, 5))
    blocks.place(PLANKS_OAK, pos(8, 3, 5))
    blocks.place(LOG_OAK, pos(0, 3, 6))
    blocks.fill(PLANKS_OAK, pos(1, 3, 6), pos(7, 3, 6))
    blocks.place(LOG_OAK, pos(8, 3, 6))
    blocks.fill(PLANKS_SPRUCE, pos(0, 4, 0), pos(8, 4, 0))
    blocks.fill(PLANKS_SPRUCE, pos(0, 4, 1), pos(8, 4, 1))
    blocks.place(PLANKS_OAK, pos(0, 4, 2))
    blocks.place(PLANKS_OAK, pos(8, 4, 2))
    blocks.place(PLANKS_OAK, pos(0, 4, 3))
    blocks.place(PLANKS_OAK, pos(8, 4, 3))
    blocks.place(PLANKS_OAK, pos(0, 4, 4))
    blocks.place(PLANKS_OAK, pos(8, 4, 4))
    blocks.fill(PLANKS_SPRUCE, pos(0, 4, 5), pos(8, 4, 5))
    blocks.fill(PLANKS_SPRUCE, pos(0, 4, 6), pos(8, 4, 6))
    blocks.fill(PLANKS_SPRUCE, pos(0, 5, 2), pos(8, 5, 2))
    blocks.place(PLANKS_OAK, pos(0, 5, 3))
    blocks.place(PLANKS_OAK, pos(8, 5, 3))
    blocks.fill(PLANKS_SPRUCE, pos(0, 5, 4), pos(8, 5, 4))
    blocks.fill(PLANKS_SPRUCE, pos(0, 6, 3), pos(8, 6, 3))
    # ▼ 置き物（たいまつ・ドア・ホッパー等）は向きが命なので手で置く
    #   たいまつ → 図の位置 x=1, 2段目, z=1
    #   たいまつ → 図の位置 x=7, 2段目, z=1
    #   たいまつ → 図の位置 x=1, 2段目, z=5
    #   たいまつ → 図の位置 x=7, 2段目, z=5
    #   オークのドア → 図の位置 x=4, 2段目, z=6

player.on_chat("build", build)
